2021-05-05 08:52:00,253 | 17703 | proxy.proxy, open_connection, 242 | ERROR | Failed to connect to controller : [Errno 61] Connect call failed ('127.0.0.1', 6653)
2021-05-05 08:52:00,254 | 17703 | proxy.proxy, start_server, 132 | INFO | Server on ('127.0.0.1', 63333)
2021-05-05 08:52:00,254 | 17703 | proxy.proxy, start_server, 135 | INFO | Server serve forever ('127.0.0.1', 63333)
2021-05-05 08:52:03,145 | 17703 | proxy.proxy, handle_switch, 149 | INFO | Client ('127.0.0.1', 54452) is connected
2021-05-05 08:52:03,145 | 17703 | proxy.proxy, handle_switch, 155 | DEBUG | waiting data ......
2021-05-05 08:52:03,146 | 17703 | proxy.proxy, handle_switch, 157 | DEBUG | read b's0'
2021-05-05 08:52:03,146 | 17703 | proxy.proxy, handle_switch, 155 | DEBUG | waiting data ......
2021-05-05 08:52:04,148 | 17703 | proxy.proxy, handle_switch, 149 | INFO | Client ('127.0.0.1', 54453) is connected
2021-05-05 08:52:04,148 | 17703 | proxy.proxy, handle_switch, 155 | DEBUG | waiting data ......
2021-05-05 08:52:04,148 | 17703 | proxy.proxy, handle_switch, 157 | DEBUG | read b's1'
2021-05-05 08:52:04,149 | 17703 | proxy.proxy, handle_switch, 155 | DEBUG | waiting data ......
2021-05-05 08:52:05,150 | 17703 | proxy.proxy, handle_switch, 149 | INFO | Client ('127.0.0.1', 54454) is connected
2021-05-05 08:52:05,150 | 17703 | proxy.proxy, handle_switch, 155 | DEBUG | waiting data ......
2021-05-05 08:52:05,151 | 17703 | proxy.proxy, handle_switch, 157 | DEBUG | read b's2'
2021-05-05 08:52:05,151 | 17703 | proxy.proxy, handle_switch, 155 | DEBUG | waiting data ......
2021-05-05 08:52:06,154 | 17703 | proxy.proxy, handle_switch, 149 | INFO | Client ('127.0.0.1', 54455) is connected
2021-05-05 08:52:06,155 | 17703 | proxy.proxy, handle_switch, 155 | DEBUG | waiting data ......
2021-05-05 08:52:06,155 | 17703 | proxy.proxy, handle_switch, 157 | DEBUG | read b's3'
2021-05-05 08:52:06,155 | 17703 | proxy.proxy, handle_switch, 155 | DEBUG | waiting data ......
2021-05-05 08:52:07,158 | 17703 | proxy.proxy, handle_switch, 149 | INFO | Client ('127.0.0.1', 54456) is connected
2021-05-05 08:52:07,160 | 17703 | proxy.proxy, handle_switch, 155 | DEBUG | waiting data ......
2021-05-05 08:52:07,160 | 17703 | proxy.proxy, handle_switch, 157 | DEBUG | read b's4'
2021-05-05 08:52:07,161 | 17703 | proxy.proxy, handle_switch, 155 | DEBUG | waiting data ......
2021-05-05 08:52:07,731 | 17703 | root, <module>, 53 | INFO | keyboardInterrupt : 
2021-05-05 08:52:07,741 | 17703 | asyncio, default_exception_handler, 1738 | ERROR | Task was destroyed but it is pending!
task: <Task pending name='Task-1' coro=<ObservableData.search_data() done, defined at /Users/shu_ruhe/lesson/Network/ofcapture/proxy/observable.py:54> wait_for=<Future cancelled>>
2021-05-05 08:52:07,742 | 17703 | asyncio, default_exception_handler, 1738 | ERROR | Task exception was never retrieved
future: <Task finished name='Task-3' coro=<ControllerHandler.open_connection() done, defined at /Users/shu_ruhe/lesson/Network/ofcapture/proxy/proxy.py:229> exception=UnboundLocalError("local variable 'peername' referenced before assignment")>
Traceback (most recent call last):
  File "/Users/shu_ruhe/lesson/Network/ofcapture/proxy/proxy.py", line 271, in open_connection
    self.logger.debug("reconnect to {} ...".format(peername))
UnboundLocalError: local variable 'peername' referenced before assignment
2021-05-05 08:52:07,744 | 17703 | asyncio, default_exception_handler, 1738 | ERROR | Task was destroyed but it is pending!
task: <Task pending name='Task-4' coro=<SwitchHandler.start_server() done, defined at /Users/shu_ruhe/lesson/Network/ofcapture/proxy/proxy.py:125> wait_for=<Future pending cb=[<TaskWakeupMethWrapper object at 0x10c632910>()]>>
2021-05-05 08:52:07,745 | 17703 | proxy.proxy, handle_switch, 170 | INFO | Close the connection and do exit processing
2021-05-05 08:52:07,752 | 17703 | asyncio, default_exception_handler, 1738 | ERROR | Task was destroyed but it is pending!
task: <Task pending name='Task-7' coro=<SwitchHandler.handle_switch() done, defined at /Users/shu_ruhe/lesson/Network/ofcapture/proxy/proxy.py:138> wait_for=<Future pending cb=[<TaskWakeupMethWrapper object at 0x10c632fd0>()]>>
2021-05-05 08:52:07,752 | 17703 | proxy.proxy, send_data, 198 | ERROR | Connection error: Event loop is closed
2021-05-05 08:52:07,755 | 17703 | asyncio, default_exception_handler, 1738 | ERROR | Task was destroyed but it is pending!
task: <Task pending name='Task-8' coro=<SwitchHandler.send_data() done, defined at /Users/shu_ruhe/lesson/Network/ofcapture/proxy/proxy.py:176> wait_for=<Future cancelled>>
2021-05-05 08:52:07,756 | 17703 | proxy.proxy, handle_switch, 170 | INFO | Close the connection and do exit processing
2021-05-05 08:52:07,759 | 17703 | asyncio, default_exception_handler, 1738 | ERROR | Task was destroyed but it is pending!
task: <Task pending name='Task-10' coro=<SwitchHandler.handle_switch() done, defined at /Users/shu_ruhe/lesson/Network/ofcapture/proxy/proxy.py:138> wait_for=<Future pending cb=[<TaskWakeupMethWrapper object at 0x10c632d90>()]>>
2021-05-05 08:52:07,759 | 17703 | proxy.proxy, send_data, 198 | ERROR | Connection error: Event loop is closed
2021-05-05 08:52:07,762 | 17703 | asyncio, default_exception_handler, 1738 | ERROR | Task was destroyed but it is pending!
task: <Task pending name='Task-11' coro=<SwitchHandler.send_data() done, defined at /Users/shu_ruhe/lesson/Network/ofcapture/proxy/proxy.py:176> wait_for=<Future cancelled>>
2021-05-05 08:52:07,762 | 17703 | proxy.proxy, handle_switch, 170 | INFO | Close the connection and do exit processing
2021-05-05 08:52:07,766 | 17703 | asyncio, default_exception_handler, 1738 | ERROR | Task was destroyed but it is pending!
task: <Task pending name='Task-13' coro=<SwitchHandler.handle_switch() done, defined at /Users/shu_ruhe/lesson/Network/ofcapture/proxy/proxy.py:138> wait_for=<Future pending cb=[<TaskWakeupMethWrapper object at 0x10c632bb0>()]>>
2021-05-05 08:52:07,767 | 17703 | proxy.proxy, send_data, 198 | ERROR | Connection error: Event loop is closed
2021-05-05 08:52:07,770 | 17703 | asyncio, default_exception_handler, 1738 | ERROR | Task was destroyed but it is pending!
task: <Task pending name='Task-14' coro=<SwitchHandler.send_data() done, defined at /Users/shu_ruhe/lesson/Network/ofcapture/proxy/proxy.py:176> wait_for=<Future cancelled>>
2021-05-05 08:52:07,771 | 17703 | proxy.proxy, handle_switch, 170 | INFO | Close the connection and do exit processing
2021-05-05 08:52:07,775 | 17703 | asyncio, default_exception_handler, 1738 | ERROR | Task was destroyed but it is pending!
task: <Task pending name='Task-16' coro=<SwitchHandler.handle_switch() done, defined at /Users/shu_ruhe/lesson/Network/ofcapture/proxy/proxy.py:138> wait_for=<Future pending cb=[<TaskWakeupMethWrapper object at 0x10c6324f0>()]>>
2021-05-05 08:52:07,775 | 17703 | proxy.proxy, send_data, 198 | ERROR | Connection error: Event loop is closed
2021-05-05 08:52:07,778 | 17703 | asyncio, default_exception_handler, 1738 | ERROR | Task was destroyed but it is pending!
task: <Task pending name='Task-17' coro=<SwitchHandler.send_data() done, defined at /Users/shu_ruhe/lesson/Network/ofcapture/proxy/proxy.py:176> wait_for=<Future cancelled>>
2021-05-05 08:52:07,779 | 17703 | proxy.proxy, handle_switch, 170 | INFO | Close the connection and do exit processing
2021-05-05 08:52:07,782 | 17703 | asyncio, default_exception_handler, 1738 | ERROR | Task was destroyed but it is pending!
task: <Task pending name='Task-19' coro=<SwitchHandler.handle_switch() done, defined at /Users/shu_ruhe/lesson/Network/ofcapture/proxy/proxy.py:138> wait_for=<Future pending cb=[<TaskWakeupMethWrapper object at 0x10c632310>()]>>
2021-05-05 08:52:07,783 | 17703 | proxy.proxy, send_data, 198 | ERROR | Connection error: Event loop is closed
2021-05-05 08:52:07,785 | 17703 | asyncio, default_exception_handler, 1738 | ERROR | Task was destroyed but it is pending!
task: <Task pending name='Task-20' coro=<SwitchHandler.send_data() done, defined at /Users/shu_ruhe/lesson/Network/ofcapture/proxy/proxy.py:176> wait_for=<Future cancelled>>
